<?xml version="1.0"?>
<robot name="cepheus" xmlns:xacro="http://www.ros.org/wiki/xacro">
	<xacro:include filename="$(find cepheus_description)/urdf/cepheus.gazebo" />
	<xacro:include filename="$(find cepheus_description)/urdf/materials.xacro" />
	<link name="world">
		<!-- <joint name="world_joint" type="continuous">
			<axis xyz="0 0 1"/>
			<parent link="world"/>
			<origin rpy="0 0 0" xyz="0 0 0"/>
			<child link="cepheus"/>
			<dynamics damping="0" friction="0"/>
		</joint> -->
	</link>

	<!-- extra links addition START -->
	<!-- <joint name="world_joint" type="continuous">
		<axis xyz="0 0 1"/>
		<parent link="world"/>
		<origin rpy="0 0 0" xyz="0 0 0"/>
		<child link="cepheus"/>
		<dynamics damping="0" friction="0"/>
	</joint> -->
	<joint name="p1_joint" type="prismatic">
		<parent link="world"/>
		<child link="p1"/>
		<axis xyz="1 0 0"/>
		<limit lower="-100" upper="100" effort="1000" velocity="10000"/>
		<dynamics damping="0" friction="0"/>
	</joint>
	<link name="p1">
		<inertial>
			<origin
				xyz="0.0 0.0 0.0"
				rpy="0.0 0.0 0.0" />
			<mass value="0.01" />
			<inertia
				ixx="1e-2"
				ixy="0.0"
				ixz="0.0"
				iyy="1e-2"
				iyz="0.0"
				izz="1e-2" />
		</inertial>
	</link>
	<gazebo reference="p1">
		<mu1>0</mu1>
		<mu2>0</mu2>
	</gazebo>
	<transmission name="lin1">
		<type>transmission_interface/SimpleTransmission</type>
		<joint name="p1_joint">
			<hardwareInterface>hardware_interface/EffortJointInterface</hardwareInterface>
		</joint>
		<actuator name="lin_motor1">
			<hardwareInterface>EffortJointInterface</hardwareInterface>
			<mechanicalReduction>1</mechanicalReduction>
		</actuator>
	</transmission>
	<joint name="p2_joint" type="prismatic">
		<parent link="p1"/>
		<child link="p2"/>
		<axis xyz="0 1 0"/>
		<limit
			lower="-100"
			upper="100"
			effort="1000"
			velocity="10000"/>
		<dynamics
			damping="0"
			friction="0"/>
	</joint>
	<link name="p2">
		<inertial>
			<origin
				xyz="0.0 0.0 0.0"
				rpy="0.0 0.0 0.0" />
			<mass value="0.01" />
			<inertia
				ixx="1e-2"
				ixy="0.0"
				ixz="0.0"
				iyy="1e-2"
				iyz="0.0"
				izz="1e-2" />
		</inertial>
		<surface>
			<friction>
				<ode>
					<mu>0</mu>
					<mu2>0</mu2>
					<fdir1>0 1.0 0</fdir1>
					<implicit_spring_damper>true</implicit_spring_damper>
				</ode>
			</friction>
		</surface>
	</link>
	<gazebo reference="p2">
		<mu1>0</mu1>
		<mu2>0</mu2>
	</gazebo>
	<transmission name="lin2">
		<type>transmission_interface/SimpleTransmission</type>
		<joint name="p2_joint">
			<hardwareInterface>hardware_interface/EffortJointInterface</hardwareInterface>
		</joint>
		<actuator name="lin_motor2">
			<hardwareInterface>EffortJointInterface</hardwareInterface>
			<mechanicalReduction>1</mechanicalReduction>
		</actuator>
	</transmission>
	<joint name="r_joint" type="continuous">
		<axis xyz="0 0 1"/>
		<parent link="p2"/>
		<origin rpy="0 0 0" xyz="0 0 0"/>
		<child link="cepheus"/>
	</joint>
	<!-- extra links addition END -->
	<link name="cepheus">
		<inertial>
			<origin
				xyz="0.0024 0.02937 0.15711"
				rpy="0 0 0" />
			<mass value="7.11891369052411" />
			<inertia
				ixx="0.0937165866660239"
				ixy="-0.004838152027527"
				ixz="-0.00397891305009112"
				iyy="0.0905199286322999"
				iyz="-0.00257712868335304"
				izz="0.0755866683160163" />
		</inertial>
		<visual>
			<origin
				xyz="0 0 0"
				rpy="0 0 0" />
			<geometry>
				<mesh filename="package://cepheus_description/urdf/meshes/cepheus.STL" />
			</geometry>
			<material name="LightGrey"/>
		</visual>
		<collision>
			<origin
				xyz="0 0 0.215"
				rpy="0 0 0" />
			<geometry>
				<cylinder length="0.43" radius="0.2"/>
			</geometry>
		</collision>
	</link>
	<joint name="reaction_wheel_joint" type="continuous">
		<parent link="cepheus"/>
		<child link="reaction_wheel"/>
		<origin xyz="0.065 0 0.03815" rpy="0 0 0"/>
		<axis xyz="0 0 1" />
	</joint>
	<link name="reaction_wheel">
		<visual>
			<material name="silver">
				<color rgba="0.5 0.5 0.5 1"/>
			</material>
			<geometry>
				<mesh filename="package://cepheus_description/urdf/meshes/reaction_wheel.STL" />
			</geometry>
			<origin xyz="0 0 0" rpy="0 0 0"/>
		</visual>
		<inertial>
			<origin xyz="0 0 0.025" rpy="0 0 0" />
			<mass value="1"/>
			<inertia
				ixx="0"
				ixy="0"
				ixz="0"
				iyy="0"
				iyz="0"
				izz="0.00197" />
		</inertial>
	</link>
	<gazebo reference="cepheus">
		<mu1>0</mu1>
		<mu2>0</mu2>
	</gazebo>
	<transmission name="tran1">
		<type>
			transmission_interface/SimpleTransmission</type>
		<joint name="reaction_wheel_joint">
			<hardwareInterface>hardware_interface/EffortJointInterface</hardwareInterface>
		</joint>
		<actuator name="motor1">
			<hardwareInterface>EffortJointInterface</hardwareInterface>
			<mechanicalReduction>1</mechanicalReduction>
		</actuator>
	</transmission>
	<joint name="left_shoulder" type="revolute">
		<origin
			xyz="0.17271 0.091404 0.05875"
			rpy="0 0 0" />
		<parent link="cepheus" />
		<child link="left_arm" />
		<axis xyz="0 0 1" />
		<limit
			lower="-0.86"
			upper="2.54"
			effort="20"
			velocity="20" />
		<dynamics
			damping="1"
			friction="1" />
	</joint>
	<link name="left_arm">
		<inertial>
			<origin
				xyz="0.10516 0.00268 0.00996"
				rpy="0 0 0" />
			<mass value="0.07974" />
			<inertia
				ixx="0.0971318625270812"
				ixy="0.00469370636895255"
				ixz="-0.000908920687249813"
				iyy="0.0755866683160163"
				iyz="0.000665178045940108"
				izz="0.0871046527712426" />
		</inertial>
		<visual>
			<origin
				xyz="0 -0.0085 0"
				rpy="0 0 0" />
			<geometry>
				<mesh filename="package://cepheus_description/urdf/meshes/left_arm.STL" />
			</geometry>
			<material name="LightGrey"/>
		</visual>
		<collision>
			<origin
				xyz="0.08 0.0 0.01"
				rpy="0 0 0" />
			<geometry>
				<box size="0.13 0.02 0.02"/>
			</geometry>
		</collision>
	</link>
	<transmission name="tran2">
		<type>transmission_interface/SimpleTransmission</type>
		<joint name="left_shoulder">
			<hardwareInterface>hardware_interface/EffortJointInterface</hardwareInterface>
		</joint>
		<actuator name="motor2">
			<hardwareInterface>EffortJointInterface</hardwareInterface>
			<mechanicalReduction>1</mechanicalReduction>
		</actuator>
	</transmission>
	<joint name="left_elbow" type="revolute">
		<origin
			xyz="0.18120 -0.01176 -0.002"
			rpy="0 0 0" />
		<parent link="left_arm" />
		<child link="left_forearm" />
		<axis xyz="0 0 1" />
		<limit
			lower="-3.14"
			upper="1.5"
			effort="2"
			velocity="20" />
		<dynamics
			damping="1"
			friction="1" />
	</joint>
	<link name="left_forearm">
		<inertial>
			<origin
				xyz="0.06831 0.00878 0.01558"
				rpy="0 0 0" />
			<mass value="0.06392" />
			<inertia
				ixx="1"
				ixy="1"
				ixz="1"
				iyy="1"
				iyz="1"
				izz="1" />
		</inertial>
		<visual>
			<origin
				xyz="0 0 0"
				rpy="0 0 0" />
			<geometry>
				<mesh filename="package://cepheus_description/urdf/meshes/left_forearm.STL" />
			</geometry>
			<material name="LightGrey"/>
		</visual>
		<collision>
			<origin
				xyz="0.105 0.0115 0.0125"
				rpy="0 0 0" />
			<geometry>
				<box size="0.13 0.025 0.025"/>
			</geometry>
		</collision>
	</link>
	<transmission name="tran3">
		<type>transmission_interface/SimpleTransmission</type>
		<joint name="left_elbow">
			<hardwareInterface>hardware_interface/EffortJointInterface</hardwareInterface>
		</joint>
		<actuator name="motor3">
			<hardwareInterface>EffortJointInterface</hardwareInterface>
			<mechanicalReduction>1</mechanicalReduction>
		</actuator>
	</transmission>
	<joint name="left_wrist" type="fixed">
		<origin
			xyz="0.15965 0.01176 -0.00838"
			rpy="0 0 0 " />
		<parent link="left_forearm" />
		<child link="left_grip" />
		<axis xyz="0 0 1" />
		<limit
			lower="-1.570796327"
			upper="1.570796327"
			effort="1"
			velocity="10" />
		<dynamics
			damping="1"
			friction="1" />
	</joint>
	<link name="left_grip">
		<inertial>
			<origin
				xyz="0.01947 -0.00226 -0.00228"
				rpy="0 0 0" />
			<mass value="0.03547" />
			<inertia
				ixx="0.0926325136613974"
				ixy="-0.00333421740190982"
				ixz="0.00529966557344093"
				iyy="0.0752633235560557"
				iyz="0.00191940596202769"
				izz="0.0919273463968869" />
		</inertial>
		<visual>
			<origin
				xyz="0 0 0"
				rpy="0 0 0" />
			<geometry>
				<mesh filename="package://cepheus_description/urdf/meshes/left_grip.STL" />
			</geometry>
			<material name="LightGrey"/>
		</visual>
		<collision>
			<origin
				xyz="0.0375 0 0.022"
				rpy="0 0 0" />
			<geometry>
				<box size="0.085 0.07 0.05"/>
			</geometry>
		</collision>
	</link>
</robot>
